Workbook

Sheet moras
A1: NUMERO | B1: SEXO | C1: SALARIO | D1: TIPO_ASEGURAMIENTO | E1: SECTOR | F1: INDICADOR_ACTIVO | G1: INDICADOR_EXTRANJERO | H1: INDICADOR_MOROSO | I1: EDAD | J1: VALOR_ATIPICO_SALARIO | K1: VALOR_ATIPICO_EDAD | L1: SALARIO_SIN_NA | M1: Columna1
A2: 1 | B2: HOMBRE | D2: ASALARIADO | E2: SECTOR PUBLICO | F2: SI | G2: NO | H2: NO | I2: 42 | J2: =IFERROR(IF(ABS((C2-resumen!$D$3)/resumen!$D$5) > 1.96, "SI", "NO"), _xleta.NOT) -> NO | K2: =IFERROR(IF(ABS((I2-resumen!$E$3)/resumen!$E$5) > 1.96, "SI", "NO"), _xleta.NOT) -> NO | L2: =IF(ISBLANK(C2), resumen!$D$4, C2) -> 408495 | M2: =IF(ISBLANK(I2), resumen!$E$4, I2) -> 42
A3: 2 | B3: HOMBRE | C3: 3315014 | D3: PENSIONADOS EN SU PROPIO SISTEMA | E3: SECTOR PUBLICO | F3: SI | G3: NO | H3: NO | I3: 77 | J3: =IFERROR(IF(ABS((C3-resumen!$D$3)/resumen!$D$5) > 1.96, "SI", "NO"), _xleta.NOT) -> SI | K3: =IFERROR(IF(ABS((I3-resumen!$E$3)/resumen!$E$5) > 1.96, "SI", "NO"), _xleta.NOT) -> SI | L3: =IF(ISBLANK(C3), resumen!$D$4, C3) -> 3315014 | M3: =IF(ISBLANK(I3), resumen!$E$4, I3) -> 77
A4: 3 | B4: MUJER | C4: 270486.01 | D4: ASALARIADO | E4: SECTOR PRIVADO | F4: SI | G4: NO | H4: NO | I4: 45 | J4: =IFERROR(IF(ABS((C4-resumen!$D$3)/resumen!$D$5) > 1.96, "SI", "NO"), _xleta.NOT) -> NO | K4: =IFERROR(IF(ABS((I4-resumen!$E$3)/resumen!$E$5) > 1.96, "SI", "NO"), _xleta.NOT) -> NO | L4: =IF(ISBLANK(C4), resumen!$D$4, C4) -> 270486.01 | M4: =IF(ISBLANK(I4), resumen!$E$4, I4) -> 45
A5: 4 | B5: MUJER | C5: 544949.83 | D5: ASALARIADO | E5: SECTOR PRIVADO | F5: SI | G5: NO | H5: NO | I5: 49 | J5: =IFERROR(IF(ABS((C5-resumen!$D$3)/resumen!$D$5) > 1.96, "SI", "NO"), _xleta.NOT) -> NO | K5: =IFERROR(IF(ABS((I5-resumen!$E$3)/resumen!$E$5) > 1.96, "SI", "NO"), _xleta.NOT) -> NO | L5: =IF(ISBLANK(C5), resumen!$D$4, C5) -> 544949.83 | M5: =IF(ISBLANK(I5), resumen!$E$4, I5) -> 49
A6: 5 | B6: MUJER | C6: 210000 | D6: ASALARIADO | E6: SECTOR PRIVADO | F6: SI | G6: NO | H6: NO | I6: 42 | J6: =IFERROR(IF(ABS((C6-resumen!$D$3)/resumen!$D$5) > 1.96, "SI", "NO"), _xleta.NOT) -> NO | K6: =IFERROR(IF(ABS((I6-resumen!$E$3)/resumen!$E$5) > 1.96, "SI", "NO"), _xleta.NOT) -> NO | L6: =IF(ISBLANK(C6), resumen!$D$4, C6) -> 210000 | M6: =IF(ISBLANK(I6), resumen!$E$4, I6) -> 42
A7: 6 | B7: HOMBRE | C7: 397150 | D7: ASALARIADO | E7: SECTOR PRIVADO | F7: SI | G7: NO | H7: NO | I7: 44 | J7: =IFERROR(IF(ABS((C7-resumen!$D$3)/resumen!$D$5) > 1.96, "SI", "NO"), _xleta.NOT) -> NO | K7: =IFERROR(IF(ABS((I7-resumen!$E$3)/resumen!$E$5) > 1.96, "SI", "NO"), _xleta.NOT) -> NO | L7: =IF(ISBLANK(C7), resumen!$D$4, C7) -> 397150 | M7: =IF(ISBLANK(I7), resumen!$E$4, I7) -> 44
A8: 7 | B8: HOMBRE | C8: 854712 | D8: ASALARIADO | E8: SECTOR PRIVADO | F8: SI | G8: NO | H8: NO | I8: 38 | J8: =IFERROR(IF(ABS((C8-resumen!$D$3)/resumen!$D$5) > 1.96, "SI", "NO"), _xleta.NOT) -> NO | K8: =IFERROR(IF(ABS((I8-resumen!$E$3)/resumen!$E$5) > 1.96, "SI", "NO"), _xleta.NOT) -> NO | L8: =IF(ISBLANK(C8), resumen!$D$4, C8) -> 854712 | M8: =IF(ISBLANK(I8), resumen!$E$4, I8) -> 38
A9: 8 | B9: HOMBRE | C9: 401000 | D9: ASALARIADO | E9: SECTOR PRIVADO | F9: SI | G9: SI | H9: SI | I9: 36 | J9: =IFERROR(IF(ABS((C9-resumen!$D$3)/resumen!$D$5) > 1.96, "SI", "NO"), _xleta.NOT) -> NO | K9: =IFERROR(IF(ABS((I9-resumen!$E$3)/resumen!$E$5) > 1.96, "SI", "NO"), _xleta.NOT) -> NO | L9: =IF(ISBLANK(C9), resumen!$D$4, C9) -> 401000 | M9: =IF(ISBLANK(I9), resumen!$E$4, I9) -> 36
A10: 9 | B10: MUJER | C10: 264703.96 | D10: ASALARIADO | E10: SECTOR PRIVADO | F10: SI | G10: NO | H10: NO | I10: 21 | J10: =IFERROR(IF(ABS((C10-resumen!$D$3)/resumen!$D$5) > 1.96, "SI", "NO"), _xleta.NOT) -> NO | K10: =IFERROR(IF(ABS((I10-resumen!$E$3)/resumen!$E$5) > 1.96, "SI", "NO"), _xleta.NOT) -> NO | L10: =IF(ISBLANK(C10), resumen!$D$4, C10) -> 264703.96 | M10: =IF(ISBLANK(I10), resumen!$E$4, I10) -> 21
A11: 10 | B11: HOMBRE | C11: 4677126.8 | D11: ASALARIADO | E11: SECTOR PRIVADO | F11: SI | G11: NO | H11: NO | I11: 40 | J11: =IFERROR(IF(ABS((C11-resumen!$D$3)/resumen!$D$5) > 1.96, "SI", "NO"), _xleta.NOT) -> SI | K11: =IFERROR(IF(ABS((I11-resumen!$E$3)/resumen!$E$5) > 1.96, "SI", "NO"), _xleta.NOT) -> NO | L11: =IF(ISBLANK(C11), resumen!$D$4, C11) -> 4677126.8 | M11: =IF(ISBLANK(I11), resumen!$E$4, I11) -> 40
A12: 11 | B12: MUJER | C12: 1200000 | D12: ASALARIADO | E12: SECTOR PRIVADO | F12: SI | G12: NO | H12: NO | I12: 30 | J12: =IFERROR(IF(ABS((C12-resumen!$D$3)/resumen!$D$5) > 1.96, "SI", "NO"), _xleta.NOT) -> NO | K12: =IFERROR(IF(ABS((I12-resumen!$E$3)/resumen!$E$5) > 1.96, "SI", "NO"), _xleta.NOT) -> NO | L12: =IF(ISBLANK(C12), resumen!$D$4, C12) -> 1200000 | M12: =IF(ISBLANK(I12), resumen!$E$4, I12) -> 30
A13: 12 | B13: MUJER | C13: 1030132 | D13: ASALARIADO | E13: SECTOR PUBLICO | F13: SI | G13: NO | H13: SI | I13: 58 | J13: =IFERROR(IF(ABS((C13-resumen!$D$3)/resumen!$D$5) > 1.96, "SI", "NO"), _xleta.NOT) -> NO | K13: =IFERROR(IF(ABS((I13-resumen!$E$3)/resumen!$E$5) > 1.96, "SI", "NO"), _xleta.NOT) -> NO | L13: =IF(ISBLANK(C13), resumen!$D$4, C13) -> 1030132 | M13: =IF(ISBLANK(I13), resumen!$E$4, I13) -> 58
A14: 13 | B14: HOMBRE | C14: 731287.5 | D14: ASALARIADO | E14: SECTOR PUBLICO | F14: SI | G14: NO | H14: NO | I14: 40 | J14: =IFERROR(IF(ABS((C14-resumen!$D$3)/resumen!$D$5) > 1.96, "SI", "NO"), _xleta.NOT) -> NO | K14: =IFERROR(IF(ABS((I14-resumen!$E$3)/resumen!$E$5) > 1.96, "SI", "NO"), _xleta.NOT) -> NO | L14: =IF(ISBLANK(C14), resumen!$D$4, C14) -> 731287.5 | M14: =IF(ISBLANK(I14), resumen!$E$4, I14) -> 40
... A21: 20 | B21: MUJER | C21: 309820 | D21: ASEGURADO VOLUNTARIO | E21: SECTOR PRIVADO | F21: SI | G21: SI | H21: SI | I21: 52 | J21: =IFERROR(IF(ABS((C21-resumen!$D$3)/resumen!$D$5) > 1.96, "SI", "NO"), _xleta.NOT) -> NO | K21: =IFERROR(IF(ABS((I21-resumen!$E$3)/resumen!$E$5) > 1.96, "SI", "NO"), _xleta.NOT) -> NO | L21: =IF(ISBLANK(C21), resumen!$D$4, C21) -> 309820 | M21: =IF(ISBLANK(I21), resumen!$E$4, I21) -> 52
A22: 21 | B22: MUJER | D22: ASALARIADO | E22: SECTOR PRIVADO | F22: SI | G22: SI | H22: NO | I22: 28 | J22: =IFERROR(IF(ABS((C22-resumen!$D$3)/resumen!$D$5) > 1.96, "SI", "NO"), _xleta.NOT) -> NO | K22: =IFERROR(IF(ABS((I22-resumen!$E$3)/resumen!$E$5) > 1.96, "SI", "NO"), _xleta.NOT) -> NO | L22: =IF(ISBLANK(C22), resumen!$D$4, C22) -> 408495 | M22: =IF(ISBLANK(I22), resumen!$E$4, I22) -> 28
A23: 22 | B23: HOMBRE | C23: 278030 | D23: CONVENIOS ESPECIALES DE TRABAJADORES INDEPENDIENTES | E23: SECTOR PRIVADO | F23: SI | G23: NO | H23: NO | I23: 59 | J23: =IFERROR(IF(ABS((C23-resumen!$D$3)/resumen!$D$5) > 1.96, "SI", "NO"), _xleta.NOT) -> NO | K23: =IFERROR(IF(ABS((I23-resumen!$E$3)/resumen!$E$5) > 1.96, "SI", "NO"), _xleta.NOT) -> NO | L23: =IF(ISBLANK(C23), resumen!$D$4, C23) -> 278030 | M23: =IF(ISBLANK(I23), resumen!$E$4, I23) -> 59
A24: 23 | B24: HOMBRE | C24: 2124814 | D24: ASALARIADO | E24: SECTOR PRIVADO | F24: SI | G24: NO | H24: NO | I24: 32 | J24: =IFERROR(IF(ABS((C24-resumen!$D$3)/resumen!$D$5) > 1.96, "SI", "NO"), _xleta.NOT) -> NO | K24: =IFERROR(IF(ABS((I24-resumen!$E$3)/resumen!$E$5) > 1.96, "SI", "NO"), _xleta.NOT) -> NO | L24: =IF(ISBLANK(C24), resumen!$D$4, C24) -> 2124814 | M24: =IF(ISBLANK(I24), resumen!$E$4, I24) -> 32
A25: 24 | B25: HOMBRE | C25: 191744.68 | D25: ASALARIADO | E25: SECTOR PRIVADO | F25: SI | G25: NO | H25: NO | I25: 18 | J25: =IFERROR(IF(ABS((C25-resumen!$D$3)/resumen!$D$5) > 1.96, "SI", "NO"), _xleta.NOT) -> NO | K25: =IFERROR(IF(ABS((I25-resumen!$E$3)/resumen!$E$5) > 1.96, "SI", "NO"), _xleta.NOT) -> NO | L25: =IF(ISBLANK(C25), resumen!$D$4, C25) -> 191744.68 | M25: =IF(ISBLANK(I25), resumen!$E$4, I25) -> 18
A26: 25 | B26: MUJER | C26: 1117489 | D26: ASALARIADO | E26: SECTOR PUBLICO | F26: SI | G26: NO | H26: SI | I26: 36 | J26: =IFERROR(IF(ABS((C26-resumen!$D$3)/resumen!$D$5) > 1.96, "SI", "NO"), _xleta.NOT) -> NO | K26: =IFERROR(IF(ABS((I26-resumen!$E$3)/resumen!$E$5) > 1.96, "SI", "NO"), _xleta.NOT) -> NO | L26: =IF(ISBLANK(C26), resumen!$D$4, C26) -> 1117489 | M26: =IF(ISBLANK(I26), resumen!$E$4, I26) -> 36
A27: 26 | B27: HOMBRE | C27: 1451530 | D27: PENSIONADOS EN SU PROPIO SISTEMA | E27: SECTOR PUBLICO | F27: SI | G27: NO | H27: NO | I27: 62 | J27: =IFERROR(IF(ABS((C27-resumen!$D$3)/resumen!$D$5) > 1.96, "SI", "NO"), _xleta.NOT) -> NO | K27: =IFERROR(IF(ABS((I27-resumen!$E$3)/resumen!$E$5) > 1.96, "SI", "NO"), _xleta.NOT) -> NO | L27: =IF(ISBLANK(C27), resumen!$D$4, C27) -> 1451530 | M27: =IF(ISBLANK(I27), resumen!$E$4, I27) -> 62
A28: 27 | B28: HOMBRE | C28: 66700 | D28: ASALARIADO | E28: SECTOR PRIVADO | F28: SI | G28: NO | H28: NO | I28: 38 | J28: =IFERROR(IF(ABS((C28-resumen!$D$3)/resumen!$D$5) > 1.96, "SI", "NO"), _xleta.NOT) -> NO | K28: =IFERROR(IF(ABS((I28-resumen!$E$3)/resumen!$E$5) > 1.96, "SI", "NO"), _xleta.NOT) -> NO | L28: =IF(ISBLANK(C28), resumen!$D$4, C28) -> 66700 | M28: =IF(ISBLANK(I28), resumen!$E$4, I28) -> 38
A29: 28 | B29: MUJER | C29: 73410 | D29: ASALARIADO | E29: SECTOR PRIVADO | F29: SI | G29: SI | H29: NO | I29: 22 | J29: =IFERROR(IF(ABS((C29-resumen!$D$3)/resumen!$D$5) > 1.96, "SI", "NO"), _xleta.NOT) -> NO | K29: =IFERROR(IF(ABS((I29-resumen!$E$3)/resumen!$E$5) > 1.96, "SI", "NO"), _xleta.NOT) -> NO | L29: =IF(ISBLANK(C29), resumen!$D$4, C29) -> 73410 | M29: =IF(ISBLANK(I29), resumen!$E$4, I29) -> 22
A30: 29 | B30: HOMBRE | C30: 815355.66 | D30: ASALARIADO | E30: SECTOR PUBLICO | F30: SI | G30: NO | H30: NO | I30: 42 | J30: =IFERROR(IF(ABS((C30-resumen!$D$3)/resumen!$D$5) > 1.96, "SI", "NO"), _xleta.NOT) -> NO | K30: =IFERROR(IF(ABS((I30-resumen!$E$3)/resumen!$E$5) > 1.96, "SI", "NO"), _xleta.NOT) -> NO | L30: =IF(ISBLANK(C30), resumen!$D$4, C30) -> 815355.66 | M30: =IF(ISBLANK(I30), resumen!$E$4, I30) -> 42
A31: 30 | B31: HOMBRE | C31: 398125 | D31: ASALARIADO | E31: SECTOR PRIVADO | F31: SI | G31: NO | H31: NO | I31: 38 | J31: =IFERROR(IF(ABS((C31-resumen!$D$3)/resumen!$D$5) > 1.96, "SI", "NO"), _xleta.NOT) -> NO | K31: =IFERROR(IF(ABS((I31-resumen!$E$3)/resumen!$E$5) > 1.96, "SI", "NO"), _xleta.NOT) -> NO | L31: =IF(ISBLANK(C31), resumen!$D$4, C31) -> 398125 | M31: =IF(ISBLANK(I31), resumen!$E$4, I31) -> 38
A32: 31 | B32: HOMBRE | C32: 606763.96 | D32: ASALARIADO | E32: SECTOR PRIVADO | F32: SI | G32: NO | H32: NO | I32: 39 | J32: =IFERROR(IF(ABS((C32-resumen!$D$3)/resumen!$D$5) > 1.96, "SI", "NO"), _xleta.NOT) -> NO | K32: =IFERROR(IF(ABS((I32-resumen!$E$3)/resumen!$E$5) > 1.96, "SI", "NO"), _xleta.NOT) -> NO | L32: =IF(ISBLANK(C32), resumen!$D$4, C32) -> 606763.96 | M32: =IF(ISBLANK(I32), resumen!$E$4, I32) -> 39
A33: 32 | B33: HOMBRE | C33: 360420 | D33: TRABAJADOR INDEPENDIENTE | E33: SECTOR PRIVADO | F33: SI | G33: NO | H33: SI | I33: 53 | J33: =IFERROR(IF(ABS((C33-resumen!$D$3)/resumen!$D$5) > 1.96, "SI", "NO"), _xleta.NOT) -> NO | K33: =IFERROR(IF(ABS((I33-resumen!$E$3)/resumen!$E$5) > 1.96, "SI", "NO"), _xleta.NOT) -> NO | L33: =IF(ISBLANK(C33), resumen!$D$4, C33) -> 360420 | M33: =IF(ISBLANK(I33), resumen!$E$4, I33) -> 53
A34: 33 | B34: MUJER | C34: 297046 | D34: ASALARIADO | E34: SECTOR PRIVADO | F34: SI | G34: SI | H34: NO | I34: 41 | J34: =IFERROR(IF(ABS((C34-resumen!$D$3)/resumen!$D$5) > 1.96, "SI", "NO"), _xleta.NOT) -> NO | K34: =IFERROR(IF(ABS((I34-resumen!$E$3)/resumen!$E$5) > 1.96, "SI", "NO"), _xleta.NOT) -> NO | L34: =IF(ISBLANK(C34), resumen!$D$4, C34) -> 297046 | M34: =IF(ISBLANK(I34), resumen!$E$4, I34) -> 41
... A36: 35 | B36: HOMBRE | C36: 68309.03 | D36: ASALARIADO | E36: SECTOR PRIVADO | F36: SI | G36: NO | H36: NO | I36: 43 | J36: =IFERROR(IF(ABS((C36-resumen!$D$3)/resumen!$D$5) > 1.96, "SI", "NO"), _xleta.NOT) -> NO | K36: =IFERROR(IF(ABS((I36-resumen!$E$3)/resumen!$E$5) > 1.96, "SI", "NO"), _xleta.NOT) -> NO | L36: =IF(ISBLANK(C36), resumen!$D$4, C36) -> 68309.03 | M36: =IF(ISBLANK(I36), resumen!$E$4, I36) -> 43
A37: 36 | B37: HOMBRE | D37: ASALARIADO | E37: SECTOR PUBLICO | F37: SI | G37: NO | H37: NO | I37: 62 | J37: =IFERROR(IF(ABS((C37-resumen!$D$3)/resumen!$D$5) > 1.96, "SI", "NO"), _xleta.NOT) -> NO | K37: =IFERROR(IF(ABS((I37-resumen!$E$3)/resumen!$E$5) > 1.96, "SI", "NO"), _xleta.NOT) -> NO | L37: =IF(ISBLANK(C37), resumen!$D$4, C37) -> 408495 | M37: =IF(ISBLANK(I37), resumen!$E$4, I37) -> 62
A38: 37 | B38: HOMBRE | C38: 1552307.5 | D38: ASALARIADO | E38: SECTOR PRIVADO | F38: SI | G38: SI | H38: NO | I38: 41 | J38: =IFERROR(IF(ABS((C38-resumen!$D$3)/resumen!$D$5) > 1.96, "SI", "NO"), _xleta.NOT) -> NO | K38: =IFERROR(IF(ABS((I38-resumen!$E$3)/resumen!$E$5) > 1.96, "SI", "NO"), _xleta.NOT) -> NO | L38: =IF(ISBLANK(C38), resumen!$D$4, C38) -> 1552307.5 | M38: =IF(ISBLANK(I38), resumen!$E$4, I38) -> 41
A39: 38 | B39: HOMBRE | C39: 1531575 | D39: ASEGURADO VOLUNTARIO | E39: SECTOR PRIVADO | F39: SI | G39: SI | H39: NO | I39: 66 | J39: =IFERROR(IF(ABS((C39-resumen!$D$3)/resumen!$D$5) > 1.96, "SI", "NO"), _xleta.NOT) -> NO | K39: =IFERROR(IF(ABS((I39-resumen!$E$3)/resumen!$E$5) > 1.96, "SI", "NO"), _xleta.NOT) -> NO | L39: =IF(ISBLANK(C39), resumen!$D$4, C39) -> 1531575 | M39: =IF(ISBLANK(I39), resumen!$E$4, I39) -> 66
A40: 39 | B40: HOMBRE | C40: 3220569.1 | D40: ASALARIADO | E40: SECTOR PRIVADO | F40: SI | G40: NO | H40: NO | I40: 48 | J40: =IFERROR(IF(ABS((C40-resumen!$D$3)/resumen!$D$5) > 1.96, "SI", "NO"), _xleta.NOT) -> SI | K40: =IFERROR(IF(ABS((I40-resumen!$E$3)/resumen!$E$5) > 1.96, "SI", "NO"), _xleta.NOT) -> NO | L40: =IF(ISBLANK(C40), resumen!$D$4, C40) -> 3220569.1 | M40: =IF(ISBLANK(I40), resumen!$E$4, I40) -> 48
A41: 40 | B41: HOMBRE | C41: 658917 | D41: ASALARIADO | E41: SECTOR PUBLICO | F41: SI | G41: NO | H41: SI | I41: 56 | J41: =IFERROR(IF(ABS((C41-resumen!$D$3)/resumen!$D$5) > 1.96, "SI", "NO"), _xleta.NOT) -> NO | K41: =IFERROR(IF(ABS((I41-resumen!$E$3)/resumen!$E$5) > 1.96, "SI", "NO"), _xleta.NOT) -> NO | L41: =IF(ISBLANK(C41), resumen!$D$4, C41) -> 658917 | M41: =IF(ISBLANK(I41), resumen!$E$4, I41) -> 56
A42: 41 | B42: HOMBRE | C42: 631707.6 | D42: ASALARIADO | E42: SECTOR PRIVADO | F42: SI | G42: NO | H42: NO | I42: 25 | J42: =IFERROR(IF(ABS((C42-resumen!$D$3)/resumen!$D$5) > 1.96, "SI", "NO"), _xleta.NOT) -> NO | K42: =IFERROR(IF(ABS((I42-resumen!$E$3)/resumen!$E$5) > 1.96, "SI", "NO"), _xleta.NOT) -> NO | L42: =IF(ISBLANK(C42), resumen!$D$4, C42) -> 631707.6 | M42: =IF(ISBLANK(I42), resumen!$E$4, I42) -> 25
A43: 42 | B43: MUJER | C43: 977376 | D43: ASALARIADO | E43: SECTOR PRIVADO | F43: SI | G43: NO | H43: NO | I43: 33 | J43: =IFERROR(IF(ABS((C43-resumen!$D$3)/resumen!$D$5) > 1.96, "SI", "NO"), _xleta.NOT) -> NO | K43: =IFERROR(IF(ABS((I43-resumen!$E$3)/resumen!$E$5) > 1.96, "SI", "NO"), _xleta.NOT) -> NO | L43: =IF(ISBLANK(C43), resumen!$D$4, C43) -> 977376 | M43: =IF(ISBLANK(I43), resumen!$E$4, I43) -> 33
A44: 43 | B44: MUJER | C44: 278030 | D44: CONVENIOS ESPECIALES DE TRABAJADORES INDEPENDIENTES | E44: SECTOR PRIVADO | F44: SI | G44: SI | H44: NO | I44: 23 | J44: =IFERROR(IF(ABS((C44-resumen!$D$3)/resumen!$D$5) > 1.96, "SI", "NO"), _xleta.NOT) -> NO | K44: =IFERROR(IF(ABS((I44-resumen!$E$3)/resumen!$E$5) > 1.96, "SI", "NO"), _xleta.NOT) -> NO | L44: =IF(ISBLANK(C44), resumen!$D$4, C44) -> 278030 | M44: =IF(ISBLANK(I44), resumen!$E$4, I44) -> 23
A45: 44 | B45: HOMBRE | C45: 633750 | D45: ASALARIADO | E45: SECTOR PRIVADO | F45: SI | G45: NO | H45: NO | I45: 43 | J45: =IFERROR(IF(ABS((C45-resumen!$D$3)/resumen!$D$5) > 1.96, "SI", "NO"), _xleta.NOT) -> NO | K45: =IFERROR(IF(ABS((I45-resumen!$E$3)/resumen!$E$5) > 1.96, "SI", "NO"), _xleta.NOT) -> NO | L45: =IF(ISBLANK(C45), resumen!$D$4, C45) -> 633750 | M45: =IF(ISBLANK(I45), resumen!$E$4, I45) -> 43
A46: 45 | B46: MUJER | C46: 376776 | D46: ASALARIADO | E46: SECTOR PRIVADO | F46: SI | G46: NO | H46: NO | I46: 27 | J46: =IFERROR(IF(ABS((C46-resumen!$D$3)/resumen!$D$5) > 1.96, "SI", "NO"), _xleta.NOT) -> NO | K46: =IFERROR(IF(ABS((I46-resumen!$E$3)/resumen!$E$5) > 1.96, "SI", "NO"), _xleta.NOT) -> NO | L46: =IF(ISBLANK(C46), resumen!$D$4, C46) -> 376776 | M46: =IF(ISBLANK(I46), resumen!$E$4, I46) -> 27
A47: 46 | B47: MUJER | C47: 1878386.2 | D47: ASALARIADO | E47: SECTOR PRIVADO | F47: SI | G47: NO | H47: NO | I47: 28 | J47: =IFERROR(IF(ABS((C47-resumen!$D$3)/resumen!$D$5) > 1.96, "SI", "NO"), _xleta.NOT) -> NO | K47: =IFERROR(IF(ABS((I47-resumen!$E$3)/resumen!$E$5) > 1.96, "SI", "NO"), _xleta.NOT) -> NO | L47: =IF(ISBLANK(C47), resumen!$D$4, C47) -> 1878386.2 | M47: =IF(ISBLANK(I47), resumen!$E$4, I47) -> 28
...

Sheet resumen
B2: RESUMEN | C2: IDENTIFICACION | D2: SALARIO | E2: EDAD
B3: Promedio | C3: =AVERAGE(moras!A2:A5001) -> 2500.5 | D3: =AVERAGE(moras!C2:C5001) -> 657534.29 | E3: =AVERAGE(moras!I2:I5001) -> 41.906344
B4: Mediana | C4: =MEDIAN(moras!A2:A5001) -> 2500.5 | D4: =MEDIAN(moras!C2:C5001) -> 408495 | E4: =MEDIAN(moras!I2:I5001) -> 40
B5: Desviacion estandar | C5: =_xlfn.STDEV.P(moras!A2:A5001) -> 1443.3756 | D5: =_xlfn.STDEV.P(moras!C2:C5001) -> 810921.27 | E5: =_xlfn.STDEV.P(moras!I2:I5001) -> 14.167839
B6: Minimo | C6: =MIN(moras!A2:A5001) -> 1 | D6: =MIN(moras!C2:C5001) -> 10 | E6: =MIN(moras!I2:I5001) -> 14
B7: Maximo | C7: =MAX(moras!A2:A5001) -> 5000 | D7: =MAX(moras!C2:C5001) -> 16858742 | E7: =MAX(moras!I2:I5001) -> 99
B10: VALORES FALTANTES | C10: IDENTIFICACION | D10: SEXO | E10: SALARIO | F10: TIPO_ASEGURAMIENTO | G10: SECTOR | H10: INDICADOR_ACTIVO | I10: INDICADOR_EXTRANJERO | J10: INDICADOR_MOROSO | K10: EDAD | L10: VALOR_ATIPICO_SALARIO | M10: VALOR_ATIPICO_EDAD
B11: Porcentaje | C11: =COUNTBLANK(moras!A2:A5001)/COUNTA(moras!A2:A5001) -> 0 | D11: =COUNTBLANK(moras!B2:B5001)/COUNTA(moras!B2:B5001) -> 0 | E11: =COUNTBLANK(moras!C2:C5001)/COUNTA(moras!C2:C5001) -> 0.00060036022 | F11: =COUNTBLANK(moras!D2:D5001)/COUNTA(moras!D2:D5001) -> 0.0004 | G11: =COUNTBLANK(moras!E2:E5001)/COUNTA(moras!E2:E5001) -> 0 | H11: =COUNTBLANK(moras!F2:F5001)/COUNTA(moras!F2:F5001) -> 0 | I11: =COUNTBLANK(moras!G2:G5001)/COUNTA(moras!G2:G5001) -> 0 | J11: =COUNTBLANK(moras!H2:H5001)/COUNTA(moras!H2:H5001) -> 0 | ... M11: =COUNTBLANK(moras!K2:K5001)/COUNTA(moras!K2:K5001) -> 0
E12: Se modifico con mediana | F12: No se modifica, asumo que puede traer problemas legales | K12: Se modifico con mediana

Sheet graficos
AA1: Morosidad | AB1: No morosidad
B2: Hombres | C2: =COUNTIF(moras!B2:B5001, "HOMBRE") -> 3012 | Q2: Hombres | R2: Mujeres | Z2: ASALARIADO | AA2: =COUNTIFS(moras!D2:D5001,Z2,moras!H2:H5001,"SI") -> 414 | AB2: =COUNTIFS(moras!D2:D5001,Z2,moras!H2:H5001,"NO") -> 3048 | AC2: =-AB2 -> -3048
B3: Mujeres | C3: =COUNTIF(moras!B2:B5001, "MUJER") -> 1988 | P3: Morosos | Q3: =COUNTIFS(moras!B2:B5001,"HOMBRE",moras!H2:H5001,"SI") -> 534 | R3: =COUNTIFS(moras!B2:B5001,"MUJER",moras!H2:H5001,"SI") -> 336 | S3: =-R3 -> -336 | Z3: PENSIONADOS EN SU PROPIO SISTEMA | AA3: =COUNTIFS(moras!D3:D5002,Z3,moras!H3:H5002,"SI") -> 0 | AB3: =COUNTIFS(moras!D3:D5002,Z3,moras!H3:H5002,"NO") -> 212 | AC3: =-AB3 -> -212
P4: No morosos | Q4: =COUNTIFS(moras!B2:B5001,"HOMBRE",moras!H2:H5001,"NO") -> 2478 | R4: =COUNTIFS(moras!B2:B5001,"MUJER",moras!H2:H5001,"NO") -> 1652 | S4: =-R4 -> -1652 | Z4: ASEGURADO VOLUNTARIO | AA4: =COUNTIFS(moras!D4:D5003,Z4,moras!H4:H5003,"SI") -> 58 | AB4: =COUNTIFS(moras!D4:D5003,Z4,moras!H4:H5003,"NO") -> 378 | AC4: =-AB4 -> -378
Q5: =-Q4 -> -2478 | R5: =-R4 -> -1652 | Z5: TRABAJADOR INDEPENDIENTE | AA5: =COUNTIFS(moras!D5:D5004,Z5,moras!H5:H5004,"SI") -> 393 | AB5: =COUNTIFS(moras!D5:D5004,Z5,moras!H5:H5004,"NO") -> 307 | AC5: =-AB5 -> -307
Z6: CONVENIOS ESPECIALES DE TRABAJADORES INDEPENDIENTES | AA6: =COUNTIFS(moras!D6:D5005,Z6,moras!H6:H5005,"SI") -> 4 | AB6: =COUNTIFS(moras!D6:D5005,Z6,moras!H6:H5005,"NO") -> 153 | AC6: =-AB6 -> -153
Z7: CONVENIOS ESPECIALES DE ASEGURADOS VOLUNTARIOS | AA7: =COUNTIFS(moras!D7:D5006,Z7,moras!H7:H5006,"SI") -> 0 | AB7: =COUNTIFS(moras!D7:D5006,Z7,moras!H7:H5006,"NO") -> 31 | AC7: =-AB7 -> -31
Q9: Morosos | R9: No morosos
P10: Salarios | Q10: =IF(moras!H2="SI", moras!C2, "") | R10: =IF(moras!H2="NO", moras!C2, "") -> 0 | S10: =-R10 -> 0
Q11: =IF(moras!H3="SI", moras!C3, "") | R11: =IF(moras!H3="NO", moras!C3, "") -> 3315014 | S11: =-R11 -> -3315014
Q12: =IF(moras!H4="SI", moras!C4, "") | R12: =IF(moras!H4="NO", moras!C4, "") -> 270486.01 | S12: =-R12 -> -270486.01
Q13: =IF(moras!H5="SI", moras!C5, "") | R13: =IF(moras!H5="NO", moras!C5, "") -> 544949.83 | S13: =-R13 -> -544949.83 | Y13: Morosidad | Z13: No morosidad
Q14: =IF(moras!H6="SI", moras!C6, "") | R14: =IF(moras!H6="NO", moras!C6, "") -> 210000 | S14: =-R14 -> -210000 | X14: SECTOR PUBLICO | Y14: =COUNTIFS(moras!E2:E5001,X14,moras!H2:H5001,"SI") -> 166 | Z14: =COUNTIFS(moras!E2:E5001,X14,moras!H2:H5001,"NO") -> 928 | AA14: =-Z14 -> -928
Q15: =IF(moras!H7="SI", moras!C7, "") | R15: =IF(moras!H7="NO", moras!C7, "") -> 397150 | S15: =-R15 -> -397150 | X15: SECTOR PRIVADO | Y15: =COUNTIFS(moras!E3:E5002,X15,moras!H3:H5002,"SI") -> 704 | Z15: =COUNTIFS(moras!E3:E5002,X15,moras!H3:H5002,"NO") -> 3202 | AA15: =-Z15 -> -3202
Q16: =IF(moras!H8="SI", moras!C8, "") | R16: =IF(moras!H8="NO", moras!C8, "") -> 854712 | S16: =-R16 -> -854712
Q17: =IF(moras!H9="SI", moras!C9, "") -> 401000 | R17: =IF(moras!H9="NO", moras!C9, "") | S17: =-R17 -> #VALUE!
Q18: =IF(moras!H10="SI", moras!C10, "") | R18: =IF(moras!H10="NO", moras!C10, "") -> 264703.96 | S18: =-R18 -> -264703.96
Q19: =IF(moras!H11="SI", moras!C11, "") | R19: =IF(moras!H11="NO", moras!C11, "") -> 4677126.8 | S19: =-R19 -> -4677126.8
Q20: =IF(moras!H12="SI", moras!C12, "") | R20: =IF(moras!H12="NO", moras!C12, "") -> 1200000 | S20: =-R20 -> -1200000
Q21: =IF(moras!H13="SI", moras!C13, "") -> 1030132 | R21: =IF(moras!H13="NO", moras!C13, "") | S21: =-R21 -> #VALUE!
Q22: =IF(moras!H14="SI", moras!C14, "") | R22: =IF(moras!H14="NO", moras!C14, "") -> 731287.5 | S22: =-R22 -> -731287.5
Q23: =IF(moras!H15="SI", moras!C15, "") | R23: =IF(moras!H15="NO", moras!C15, "") -> 282305 | S23: =-R23 -> -282305
Q24: =IF(moras!H16="SI", moras!C16, "") | R24: =IF(moras!H16="NO", moras!C16, "") -> 343390.86 | S24: =-R24 -> -343390.86
Q25: =IF(moras!H17="SI", moras!C17, "") | R25: =IF(moras!H17="NO", moras!C17, "") -> 1943489.5 | S25: =-R25 -> -1943489.5
Q26: =IF(moras!H18="SI", moras!C18, "") -> 1108980 | R26: =IF(moras!H18="NO", moras!C18, "") | S26: =-R26 -> #VALUE!
Q27: =IF(moras!H19="SI", moras!C19, "") | R27: =IF(moras!H19="NO", moras!C19, "") -> 133157 | S27: =-R27 -> -133157
Q28: =IF(moras!H20="SI", moras!C20, "") | R28: =IF(moras!H20="NO", moras!C20, "") -> 553939 | S28: =-R28 -> -553939
Q29: =IF(moras!H21="SI", moras!C21, "") -> 309820 | R29: =IF(moras!H21="NO", moras!C21, "") | S29: =-R29 -> #VALUE! | Y29: Morosidad | Z29: No morosidad
Q30: =IF(moras!H22="SI", moras!C22, "") | R30: =IF(moras!H22="NO", moras!C22, "") -> 0 | S30: =-R30 -> 0 | X30: SI | Y30: =COUNTIFS(moras!F2:F5001,X30,moras!H2:H5001,"SI") -> 852 | Z30: =COUNTIFS(moras!F2:F5001,X30,moras!H2:H5001,"NO") -> 4114 | AA30: =-Z30 -> -4114
Q31: =IF(moras!H23="SI", moras!C23, "") | R31: =IF(moras!H23="NO", moras!C23, "") -> 278030 | S31: =-R31 -> -278030 | X31: NO | Y31: =COUNTIFS(moras!F3:F5002,X31,moras!H3:H5002,"SI") -> 18 | Z31: =COUNTIFS(moras!F2:F5001,X31,moras!H2:H5001,"NO") -> 16 | AA31: =-Z31 -> -16
Q32: =IF(moras!H24="SI", moras!C24, "") | R32: =IF(moras!H24="NO", moras!C24, "") -> 2124814 | S32: =-R32 -> -2124814
Q33: =IF(moras!H25="SI", moras!C25, "") | R33: =IF(moras!H25="NO", moras!C25, "") -> 191744.68 | S33: =-R33 -> -191744.68
Q34: =IF(moras!H26="SI", moras!C26, "") -> 1117489 | R34: =IF(moras!H26="NO", moras!C26, "") | S34: =-R34 -> #VALUE!
Q35: =IF(moras!H27="SI", moras!C27, "") | R35: =IF(moras!H27="NO", moras!C27, "") -> 1451530 | S35: =-R35 -> -1451530
Q36: =IF(moras!H28="SI", moras!C28, "") | R36: =IF(moras!H28="NO", moras!C28, "") -> 66700 | S36: =-R36 -> -66700
Q37: =IF(moras!H29="SI", moras!C29, "") | R37: =IF(moras!H29="NO", moras!C29, "") -> 73410 | S37: =-R37 -> -73410
Q38: =IF(moras!H30="SI", moras!C30, "") | R38: =IF(moras!H30="NO", moras!C30, "") -> 815355.66 | S38: =-R38 -> -815355.66
Q39: =IF(moras!H31="SI", moras!C31, "") | R39: =IF(moras!H31="NO", moras!C31, "") -> 398125 | S39: =-R39 -> -398125
Q40: =IF(moras!H32="SI", moras!C32, "") | R40: =IF(moras!H32="NO", moras!C32, "") -> 606763.96 | S40: =-R40 -> -606763.96
B41: TIPO_ASEGURAMIENTO | Q41: =IF(moras!H33="SI", moras!C33, "") -> 360420 | R41: =IF(moras!H33="NO", moras!C33, "") | S41: =-R41 -> #VALUE!
...
